Workbook

Sheet Dashboard
A1: POLİSAN KİMYA — MERKEZİ İŞLETME YÖNETİM PANELİ
A2: Güncelleme: 09.10.2026 | Hazırlayan: Orhan KARABA | Tüm veriler kaynak dosyalardan derlenmiştir
A4: ▶ PROJE ÖZETİ
A5: TOPLAM PROJE | C5: DEVAM EDEN | E5: TAMAMLANAN | G5: PLANLANAN BÜTÇE (TL) | J5: GERÇEKLEŞİN (TL) | L5: AKSİYON SAYISI
A6: 2 | C6: 2 | E6: =COUNTIF(Projeler!Y:Y,"Tamamlandı") -> 0 | G6: 42429489 | J6: 0 | L6: 11
A8: ▶ TANK ENVANTERİ DURUMU
A9: TOPLAM TANK | C9: UYGUN | E9: UYGUN DEĞİL / UYGUNSUZ | H9: GECİKMİŞ KONTROL | J9: 30 GÜN İÇİNDE | L9: 90 GÜN İÇİNDE
A10: 139 | C10: =COUNTIF(Tank_Envanteri!Q:Q,"Uygun") -> 82 | E10: =COUNTIFS(Tank_Envanteri!Q:Q,"Uygun Değil")+COUNTIFS(Tank_Envanteri!Q:Q,"Uygunsuz") -> 18 | H10: =COUNTIF(Tank_Envanteri!P:P,"GECİKMİŞ") -> 0 | J10: =COUNTIF(Tank_Envanteri!P:P,"30 GÜN İÇİNDE") -> 0 | L10: =COUNTIF(Tank_Envanteri!P:P,"90 GÜN İÇİNDE") -> 0
A12: ▶ RİSK, UYGUNSUZLUK VE HAZOP AKSİYONLARI
A13: TOPLAM RİSK KAYDI | C13: HAZOP AKSİYONU | E13: TANK UYGUNSUZLUĞU | G13: KRİTİK RİSK | J13: YÜKSEK RİSK | L13: AÇIK AKSİYON
A14: =COUNTA(Risk_Uygunsuzluk!A:A)-3 -> 240 | C14: 220 | E14: 18 | G14: =COUNTIF(Risk_Uygunsuzluk!M:M,"KRİTİK") -> 24 | J14: =COUNTIF(Risk_Uygunsuzluk!M:M,"YÜKSEK") -> 97 | L14: =COUNTIF(Risk_Uygunsuzluk!P:P,"Açık") -> 240
A16: ▶ MALİYET MERKEZİ — OCAK-MART 2025 GERÇEKLEŞMELER (SAP)
A17: TOPLAM GİDER (Oca-Mar 2025) | D17: KAZAN DAİRESİ | G17: ELEKTRİK ATÖLYESİ | J17: DİĞER MASRAF YERLERİ
A18: 15078684 | D18: 7808809.9 | G18: 0 | J18: 7269874.4
A20: ▶ VERİ KALİTESİ VE EKSİKLİKLER
A21: AÇIK VERİ KALİTESİ SORUNU | C21: HAZOP SORUMLU EKSİK | E21: MALİYET DÖNEMİ KAYNAK SAYISI | G21: DOKÜMAN KAYDI | J21: KAYNAK DOSYA SAYISI | L21: SON GÜNCELLEME
A22: =COUNTIF(Veri_Kalitesi!G:G,"Açık") -> 10 | C22: 220 | E22: =COUNTA(Butce_Maliyet!A:A)-3 -> 598 | G22: =COUNTA(Dokuman_Yonetimi!A:A)-2 -> 5 | J22: 5 | L22: 09.10.2026
A24: Sayfalar: Projeler | Proje_Aksiyonlar | Gunluk_Is_Takibi | Tank_Envanteri | Tank_Muayene_Log | Dolum_Hortumlari | Ekipman_Envanteri | Bakim_Gecmisi | Butce_Maliyet | Satin_Alma | Risk_Uygunsuzluk | Dokuman_Yonetimi | Tanimlar | Veri_Kalitesi | Kaynak_Dosyalar

Sheet Kaynak_Dosyalar
A1: KAYNAK DOSYA ENVANTERİ
A2: Dosya_ID | B2: Dosya_Adı | C2: Dosya_Türü | D2: Modül | E2: Sayfa / Kapsam | F2: Kayıt_Sayısı | G2: İçerik_Özeti | H2: Veri_Kalitesi_Notu
A3: KYN-001 | B3: HAZOP_Aksiyonlar_Excel_Aksiyon_Listesi_20260923_151212.xlsx | C3: HAZOP Aksiyon Listesi | D3: Risk & Aksiyon | E3: HAZOP_Aksiyonlar_Excel / AKSIYON_LISTESI / AKSIYON_KONTROL | F3: 220 aksiyon | G3: Gümüş Tesisi HAZOP çalışmasından elde edilen aksiyon listesi. AKSİYON_NO sütunuyla her aksiyon numaralandırılmış. | H3: Ekipman tag bilgisi bazı satırlarda boş; sorumlu/termin verisi mevcut değil.
A4: KYN-002 | B4: Final_-_Orhan_KARABA-_Mekanik_Elektrik.xlsx | C4: SAP Maliyet Verisi | D4: Bütçe & Maliyet | E4: Fatura Bazlı Detay (585 kayıt) + 12 özet sayfa | F4: 585 fatura kaydı | G4: Oca-Mar 2025 dönemi SAP fiili giderleri. Masraf yeri, ana hesap ve belge bazında detaylı. 13 farklı maliyet merkezi. | H4: Planlanan/bütçe değeri yok; yalnızca gerçekleşen. Mart 2025 eksik dönem.
A5: KYN-003 | B5: Polisan_Kimya_Tank_Verileri_2026.xlsx | C5: Tank Envanteri | D5: Tank Envanteri | E5: 7 sayfa (Tank Listesi + 6 alan) | F5: 139 tank | G5: Polisan Kimya tüm tank envanteri. Kontrol tarihi, standart, kapasite, kimyasal ve durum bilgileri mevcut. | H5: "Uygun Değil" tanklar için yalnızca "Out of service raporu yok" notu var; kapanış tarihi, sorumlu yok.
A6: KYN-004 | B6: Pilot_Reaktor_Tasınma_Maliyeti.xlsx | C6: Proje Maliyet Analizi | D6: Projeler | E6: ÖZET / GİRDİLER / MALİYET / ZAMAN | F6: 1 proje, ~80 kalem | G6: Pilot reaktör odasının taşınma maliyet analizi. Doküman: POL-MBO-PRT-2026-001 Rev.01. Toplam: 2.129.489 TL (KDV hariç). | H6: Elektrik kalemi (6. bölüm) sıfır; bilgi bekleniyor. Süreler varsayımlı.
A7: KYN-005 | B7: POL-MBO-ADS-2026-002_Rev02.xlsx | C7: Yatırım Fizibilite | D7: Projeler | E7: 0-Ozet / 1-Hacim / 2-Hidrolik / 3-Ortak / 4-Senaryo / 5-Riskler | F7: 4 senaryo karşılaştırması | G7: Reçine Tesisi Reaktör Acil Durum Drain Sistemi. Senaryo A (Yerüstü 50m³) önerilen: ~40,3 M TL CAPEX. Doküman: POL-MBO-ADS-2026-002 Rev.02. | H7: AACE Class 4 tahmin (-%20/+%30). Hiçbir kalem alınmış teklif değil.

Sheet Tanimlar
A1: TANIMLAR VE REFERANS LİSTELER
A2: PROJE DURUM | B2: TANK DURUM | C2: RİSK SEVİYESİ | D2: ÖNCELİK | E2: AKSIYON DURUM | F2: TESİS | G2: PROJE KATEGORİSİ | H2: MASRAF YERLERİ | I2: STANDARTLAR | J2: HORTUM DURUM | K2: MUAYENEPERİYOT | L2: PARA BİRİMİ
A3: Planlama | B3: Uygun | C3: KRİTİK | D3: 1-Acil | E3: Açık | F3: Gümüş Tesisi | G3: Yatırım | H3: ALT YAPI HIZMETLERI | I3: API 650 | J3: Aktif | K3: Yıllık | L3: TRY
A4: Onay Bekliyor | B4: Uygun Değil | C4: YÜKSEK | D4: 2-Yüksek | E4: Devam Ediyor | F4: ADR Tank Sahası | G4: Bakım-Onarım | H4: ELEKTRİK ATÖLYESİ | I4: API 653 | J4: Bakımda | K4: 3 Yıllık | L4: USD
A5: Devam Ediyor | B5: Uygunsuz | C5: ORTA | D5: 3-Orta | E5: Gecikmiş | F5: Reçine Tesisi | G5: İyileştirme | H5: JENERATOR HİZMETLERİ | I5: API 510 | J5: Kullanım Dışı | K5: 5 Yıllık | L5: EUR
A6: Askıya Alındı | B6: Kullanım Dışı /Uygun | C6: DÜŞÜK | D6: 4-Düşük | E6: Tamamlandı | F6: Dilovası Yapı Kim. | G6: Revizyon | H6: KAZAN DAİRESİ | I6: TS EN 12285-2 | J6: Değişim Gerekli | K6: 10 Yıllık
A7: Tamamlandı | B7: Kontrolü yok | E7: İptal | F7: AUS Tank Sahası | G7: Güvenlik | H7: KOMPRESÖR HİZMETLERİ | I7: API 510 / API 653 | J7: Hurdaya Ayrıldı | K7: Out of service 10 yıl / In Service 5 yıl
A8: İptal | B8: Bilgi Bekleniyor | F8: Reçine Yardımcı | G8: Çevre | H8: TEKNİK ORTAK HİZM. | I8: IEC 60079-32-1
F9: Yardımcı İşl. | G9: Altyapı | H9: TEKNİK AMBAR | I9: AACE Class 4
F10: Ortak Alan | G10: Ar-Ge | H10: SU ÜRETİM
H11: SU ARITMA
H12: MEKANİK ATÖLYE
H13: DİĞER

Sheet Projeler
A1: PROJE YÖNETİM TABLOSU
A2: PRJ_ID | B2: Proje_Adı | C2: Tesis | D2: Kategori | E2: Açıklama / Kapsam | F2: Teknik_Gerekçe | G2: Fayda | H2: Öncelik | I2: Risk_Seviyesi | J2: Sorumlu | K2: Talep_Tarihi | L2: Plan_Baslangic | M2: Plan_Bitis | N2: Ger_Baslangic | O2: Ger_Bitis | P2: Aşama | Q2: İlerleme_% | R2: Plan_Butce_TL | S2: Teklif_TL | T2: Siparis_TL | U2: Ger_Harcama_TL | V2: Kalan_Butce_TL | W2: Butce_Sapmasi_% | X2: Belge_No | Y2: Durum | Z2: Sonraki_Aksiyon | AA2: Aks_Sorumlu | AB2: Aks_Termin | AC2: Gecikme_Nedeni | AD2: Son_Guncelleme
A3: PRJ-2026-001 | B3: Pilot Reaktör Odası Taşınması | C3: Reçine Tesisi | D3: Taşıma / Yeniden Düzenleme | E3: Pilot reaktör odasının (yemekhane yanı) Ar-Ge arkasındaki alana taşınması | F3: Mevcut pilot reaktör odası konumu operasyonel açıdan uygun değil; kapasite ve güvenlik gerekliliklerini karşılamıyor. | G3: İşletme güvenliğinin artırılması, proses verimliliği ve ar-ge kapasitesinin iyileştirilmesi | H3: 2-Yüksek | I3: ORTA | J3: Orhan KARABA | K3: 01.09.2026 | L3: 01.10.2026 | M3: 01.12.2026 | P3: Planlama / Maliyet Analizi | Q3: 0.1 | R3: 2129488.9 | S3: 2129488.9 | T3: 0 | U3: 0 | V3: =R3-T3 -> 2129488.9 | W3: =IFERROR((T3-R3)/R3,"") -> -1 | X3: POL-MBO-PRT-2026-001 Rev.01 | Y3: Devam Ediyor | Z3: Elektrik bağlantısı kapsamının netleştirilmesi (Kalem 6 sıfır); kot ölçümü ve mühendislik onayı | AA3: Orhan KARABA | AB3: 30.10.2026 | AD3: 09.10.2026
A4: PRJ-2026-002 | B4: Reçine Tesisi Reaktör Acil Durum Drain (Dump) Sistemi | C4: Reçine Tesisi | D4: Güvenlik / Yatırım | E4: Reçine tesisi reaktörlerinin (R-101 ile R-106) acil durum boşaltma sistemi kurulumu. 50 m³ nominal dump tankı ve bağlantı hatları. | F4: HAZOP çalışmasında reaktör acil boşaltma altyapısı eksikliği kritik risk olarak tespit edildi. LOPA gereksinimleri karşılanmalı. | G4: Yangın/patlama riski eliminasyonu, düzenleyici uyumluluk, operasyonel güvenilirlik artışı | H4: 1-Acil | I4: KRİTİK | J4: Orhan KARABA | K4: 01.09.2026 | L4: 01.11.2026 | M4: 30.06.2027 | P4: Fizibilite / Senaryo Analizi | Q4: 0.15 | R4: 40300000 | S4: 0 | T4: 0 | U4: 0 | V4: =R4-T4 -> 40300000 | W4: =IFERROR((T4-R4)/R4,"") -> -1 | X4: POL-MBO-ADS-2026-002 Rev.02 | Y4: Devam Ediyor | Z4: Kot etüdü ve DN200 kollektör mesafe ölçümü; Senaryo A vs B final karar; HAZOP revizyonu; tedarikçi teklif toplama | AA4: Orhan KARABA | AB4: 30.10.2026 | AC4: UF reaktör hacmi ve fenolik swell doğrulanmadan hacim kesinleşmez | AD4: 09.10.2026

Sheet Proje_Aksiyonlar
A1: PROJE AKSİYONLARI
A2: AKS_ID | B2: PRJ_ID | C2: Proje_Adı | D2: Aksiyon_Açıklaması | E2: Kategori | F2: Sorumlu | G2: Acilis_Tarihi | H2: Termin | I2: Durum | J2: Öncelik | K2: Tamamlanma_Tarihi | L2: Gecikme_Gun | M2: Notlar | N2: Son_Güncelleme
A3: PA-001 | B3: PRJ-2026-001 | C3: =IFERROR(INDEX(Projeler!B:B,MATCH(B3,Projeler!A:A,0)),"") -> Pilot Reaktör Odası Taşınması | D3: Elektrik bağlantısı kapsamı netleştirilecek (kablo metrajı, pano konumu belirlenmeli) | E3: Mühendislik / Kapsam | F3: Orhan KARABA | G3: 46296 | H3: 46325 | I3: Açık | J3: 1-Acil | L3: =IF(OR(I3="Tamamlandı",I3="İptal"),"",IF(TODAY()-H3>0,TODAY()-H3,"")) | M3: Elektrik kapsamı netleşmeden maliyet analizi tamamlanamaz | N3: 46304
A4: PA-002 | B4: PRJ-2026-001 | C4: =IFERROR(INDEX(Projeler!B:B,MATCH(B4,Projeler!A:A,0)),"") -> Pilot Reaktör Odası Taşınması | D4: Betopan demontaj birim fiyatı teyidi (PH.INS.035 yarı fiyatı varsayım) | E4: Teknik / Sözleşme | F4: Orhan KARABA | G4: 46296 | H4: 46325 | I4: Açık | J4: 2-Yüksek | L4: =IF(OR(I4="Tamamlandı",I4="İptal"),"",IF(TODAY()-H4>0,TODAY()-H4,"")) | M4: Açık madde: protokolde demontaj pozu yok | N4: 46304
A5: PA-003 | B5: PRJ-2026-001 | C5: =IFERROR(INDEX(Projeler!B:B,MATCH(B5,Projeler!A:A,0)),"") -> Pilot Reaktör Odası Taşınması | D5: İzolasyon demontajı yevmiye sayısı doğrulanacak (6 vs 8 yevmiye açıklığı) | E5: Teknik / Kapsam | F5: Orhan KARABA | G5: 46296 | H5: 46326 | I5: Açık | J5: 3-Orta | L5: =IF(OR(I5="Tamamlandı",I5="İptal"),"",IF(TODAY()-H5>0,TODAY()-H5,"")) | M5: Kullanıcı 6 yevmiye verdi; maliyet hesabında 8 kullanıldı | N5: 46304
A6: PA-004 | B6: PRJ-2026-001 | C6: =IFERROR(INDEX(Projeler!B:B,MATCH(B6,Projeler!A:A,0)),"") -> Pilot Reaktör Odası Taşınması | D6: Yüklenici teklif alınması (en az 3 tedarikçi) | E6: Satın Alma | F6: Orhan KARABA | G6: 46327 | H6: 46357 | I6: Açık | J6: 2-Yüksek | L6: =IF(OR(I6="Tamamlandı",I6="İptal"),"",IF(TODAY()-H6>0,TODAY()-H6,"")) | M6: Mevcut maliyet AACE Class 4 tahmin | N6: 46304
A7: PA-005 | B7: PRJ-2026-002 | C7: =IFERROR(INDEX(Projeler!B:B,MATCH(B7,Projeler!A:A,0)),"") -> Reçine Tesisi Reaktör Acil Durum Drain (Dump) Sistemi | D7: Kot etüdü: reaktör dip nozulu ile dump tankı yükseklik farkı ≥4m doğrulanacak | E7: Mühendislik / Saha | F7: Orhan KARABA | G7: 46304 | H7: 46325 | I7: Açık | J7: 1-Acil | L7: =IF(OR(I7="Tamamlandı",I7="İptal"),"",IF(TODAY()-H7>0,TODAY()-H7,"")) | M7: Senaryo A için kritik: kot <4m ise yerçekimiyle çalışmaz | N7: 46304
A8: PA-006 | B8: PRJ-2026-002 | C8: =IFERROR(INDEX(Projeler!B:B,MATCH(B8,Projeler!A:A,0)),"") -> Reçine Tesisi Reaktör Acil Durum Drain (Dump) Sistemi | D8: R-105/R-106 dolu hacmi ve R-101/R-102 çalışma hacminin teyidi | E8: Proses / Mühendislik | F8: Orhan KARABA | G8: 46304 | H8: 46326 | I8: Açık | J8: 1-Acil | L8: =IF(OR(I8="Tamamlandı",I8="İptal"),"",IF(TODAY()-H8>0,TODAY()-H8,"")) | M8: 50 m³ tank hacmi bu verilere göre seçildi | N8: 46304
A9: PA-007 | B9: PRJ-2026-002 | C9: =IFERROR(INDEX(Projeler!B:B,MATCH(B9,Projeler!A:A,0)),"") -> Reçine Tesisi Reaktör Acil Durum Drain (Dump) Sistemi | D9: ARC/VSP2 kalorimetre (fenolik) → DIERS hesabı | E9: Güvenlik / Test | F9: Orhan KARABA | G9: 46327 | H9: 46419 | I9: Açık | J9: 1-Acil | L9: =IF(OR(I9="Tamamlandı",I9="İptal"),"",IF(TODAY()-H9>0,TODAY()-H9,"")) | M9: UF reaktör swell fenolik 1,25 varsayımı doğrulanmadan hacim kesinleşmez | N9: 46304
A10: PA-008 | B10: PRJ-2026-002 | C10: =IFERROR(INDEX(Projeler!B:B,MATCH(B10,Projeler!A:A,0)),"") -> Reçine Tesisi Reaktör Acil Durum Drain (Dump) Sistemi | D10: DN200 kollektör güzergah saha ölçümü (25m kabul edildi) | E10: Mühendislik / Saha | F10: Orhan KARABA | G10: 46304 | H10: 46326 | I10: Açık | J10: 2-Yüksek | L10: =IF(OR(I10="Tamamlandı",I10="İptal"),"",IF(TODAY()-H10>0,TODAY()-H10,"")) | M10: Her 10m ek hat süreyi ~%8 artırır | N10: 46304
A11: PA-009 | B11: PRJ-2026-002 | C11: =IFERROR(INDEX(Projeler!B:B,MATCH(B11,Projeler!A:A,0)),"") -> Reçine Tesisi Reaktör Acil Durum Drain (Dump) Sistemi | D11: HAZOP revizyonu: kollektör fail-safe mantığı ve ürün karışımı uyumluluğu | E11: Güvenlik / HAZOP | F11: Orhan KARABA | G11: 46327 | H11: 46357 | I11: Açık | J11: 1-Acil | L11: =IF(OR(I11="Tamamlandı",I11="İptal"),"",IF(TODAY()-H11>0,TODAY()-H11,"")) | N11: 46304
A12: PA-010 | B12: PRJ-2026-002 | C12: =IFERROR(INDEX(Projeler!B:B,MATCH(B12,Projeler!A:A,0)),"") -> Reçine Tesisi Reaktör Acil Durum Drain (Dump) Sistemi | D12: Tank / dump vanası / kaplama için 3 tedarikçiden teklif alınması | E12: Satın Alma | F12: Orhan KARABA | G12: 46327 | H12: 46357 | I12: Açık | J12: 2-Yüksek | L12: =IF(OR(I12="Tamamlandı",I12="İptal"),"",IF(TODAY()-H12>0,TODAY()-H12,"")) | M12: Hiçbir kalem alınmış teklif değil; AACE Class 4 | N12: 46304
A13: PA-011 | B13: PRJ-2026-002 | C13: =IFERROR(INDEX(Projeler!B:B,MATCH(B13,Projeler!A:A,0)),"") -> Reçine Tesisi Reaktör Acil Durum Drain (Dump) Sistemi | D13: Tie-in işlerinin planlı TAM penceresine alınması | E13: Planlama / TAM | F13: Orhan KARABA | G13: 46327 | H13: 46388 | I13: Açık | J13: 2-Yüksek | L13: =IF(OR(I13="Tamamlandı",I13="İptal"),"",IF(TODAY()-H13>0,TODAY()-H13,"")) | N13: 46304

Sheet Gunluk_Is_Takibi
A1: GÜNLÜK İŞ VE AKSİYON TAKİBİ
A2: IS_ID | B2: İş_Açıklaması | C2: İlgili_PRJ | D2: Ekipman_Tag | E2: İş_Kategorisi | F2: Talep_Eden | G2: Sorumlu | H2: Acilis_Tarihi | I2: Termin | J2: Öncelik | K2: Durum | L2: Bekleme_Nedeni | M2: Son_İşlem | N2: Sonraki_Adım | O2: Tamamlanma | P2: Notlar
A3: IS-001 | B3: Tank havuzu sızdırmazlık ve statik yük raporu alınacak (T-303 çevresi) | C3: PRJ-2026-002 | D3: T-303 | E3: Teknik İnceleme / Rapor | F3: HAZOP Ekibi | G3: Orhan KARABA | H3: 23.09.2026 | I3: 30.10.2026 | J3: 1-Acil | K3: Açık | L3: HAZOP A-003 aksiyonundan kaynaklanıyor | N3: Muayene firmasına talep gönderilecek
A4: IS-002 | B4: LS-02 SIL sertifikalı seviye transmitteri T-303'e kurulumu | C4: PRJ-2026-002 | D4: T-303 / LS-02 | E4: Enstrüman Montajı | F4: HAZOP Ekibi | G4: Orhan KARABA | H4: 23.09.2026 | I4: 31.12.2026 | J4: 1-Acil | K4: Açık | L4: Cihaz temin ve montaj programı bekleniyor | N4: Teknik şartname hazırlanacak; tedarikçi araştırması
A5: IS-003 | B5: Metanol tankı (T-303) kumlamalı boya bakımı | D5: T-303 / Metanol Tankı | E5: Mekanik Bakım | F5: Bakım Mühendisi | G5: Orhan KARABA | H5: 01.10.2026 | I5: 31.03.2027 | J5: 2-Yüksek | K5: Açık | L5: Bütçe onayı bekleniyor | M5: Tank muayene raporunda "korozyon çok şiddetli" notu var | N5: Bütçe talebini hazırla; iş izni planla
A6: IS-004 | B6: UFC+FA Geçiş Tankı tavan korkulukları revizyonu | D6: UFC+FA Geçiş Tankı (602) | E6: Mekanik Bakım | F6: Bakım Mühendisi | G6: Orhan KARABA | H6: 01.10.2026 | I6: 31.12.2026 | J6: 3-Orta | K6: Açık | M6: Kontrol raporunda "tavan korkulukları revizyon gerekli" notu var | N6: Ölçüm ve çizim hazırlanacak; iş izni
A7: IS-005 | B7: Formaldehit tankları (201-502) Out-of-service muayene raporu eksikliği | D7: FORMALDEHİT TANKI 201/301/302/501/502/101/300 | E7: Muayene / Uygunluk | F7: Teknik Güvenlik | G7: Orhan KARABA | H7: 01.10.2026 | I7: 31.12.2026 | J7: 1-Acil | K7: Açık | L7: Akredite muayene firması program bekleniyor | M7: 7 tank uygun değil; sadece in-service raporu mevcut | N7: Muayene firmasına yazı gönderilecek; out-of-service takvim belirlenecek
A8: IS-006 | B8: ADS projesi senaryo A/B final karar ve onay | C8: PRJ-2026-002 | E8: Proje Kararı | F8: Yönetim | G8: Orhan KARABA | H8: 01.10.2026 | I8: 15.11.2026 | J8: 1-Acil | K8: Açık | L8: Kot etüdü sonucu bekleniyor (PA-005) | N8: Kot etüdü tamamlanınca yönetime sunum yapılacak

Sheet Tank_Envanteri
A1: TANK ENVANTERİ — TÜM TESİSLER
A2: TANK_ID | B2: Kaynak_Sayfa | C2: Tesis | D2: SN | E2: Tank_Adı | F2: Tank_No_ID | G2: Hacim_m3 | H2: Kimyasal | I2: Tank_Tipi | J2: Malzeme | K2: Standart | L2: Muayene_Periyot | M2: Son_Kontrol | N2: Sonraki_Kontrol | O2: Kalan_Gun | P2: Uyarı_Durumu | Q2: Durum | R2: Rapor_No | S2: Açıklama | T2: Son_Güncelleme
A3: T-001 | B3: Tank Listesİ | C3: Gümüş Tesisi | D3: 1.0 | E3: ANA KOSTIK TANKI(st61m3) | F3: 703.0 | G3: 64 | H3: KOSTİK | I3: Ayaklı tank | K3: TS EN 12285 -2 / API- 510 | L3: Yıllık | M3: 2025-03-24 00:00:00 | N3: 2026-03-24 00:00:00 | O3: =IFERROR(IF(N3="","",DATEVALUE(TEXT(N3,"DD.MM.YYYY"))-TODAY()),"Tarih Yok") -> Tarih Yok | P3: =IFERROR(IF(N3="","Tarih Yok",IF(DATEVALUE(TEXT(N3,"DD.MM.YYYY"))<TODAY(),"GECİKMİŞ",IF(DATEVALUE(TEXT(N3,"DD.MM.YYYY"))-TODAY()<=30,"30 GÜN İÇİNDE",IF(DATEVALUE(TEXT(N3,"DD.MM.YYYY"))-TODAY()<=90,"90 GÜN İÇİNDE","Takvimdeyiz")))),"Tarih Kontrol") -> Tarih Kontrol | Q3: Uygun | S3: UYGUN | T3: 09.10.2026
A4: T-002 | B4: Tank Listesİ | C4: Gümüş Tesisi | D4: 2.0 | E4: UFC+FA GEÇİŞ TANKI | F4: 602.0 | G4: 110 | H4: UFC | I4: Ayaklı tank | K4: TS EN 12285 -2 / API- 510 | L4: Yıllık | M4: 2025-04-08 00:00:00 | N4: 2026-04-08 00:00:00 | O4: =IFERROR(IF(N4="","",DATEVALUE(TEXT(N4,"DD.MM.YYYY"))-TODAY()),"Tarih Yok") -> Tarih Yok | P4: =IFERROR(IF(N4="","Tarih Yok",IF(DATEVALUE(TEXT(N4,"DD.MM.YYYY"))<TODAY(),"GECİKMİŞ",IF(DATEVALUE(TEXT(N4,"DD.MM.YYYY"))-TODAY()<=30,"30 GÜN İÇİNDE",IF(DATEVALUE(TEXT(N4,"DD.MM.YYYY"))-TODAY()<=90,"90 GÜN İÇİNDE","Takvimdeyiz")))),"Tarih Kontrol") -> Tarih Kontrol | Q4: Uygun | S4: TAVAN KORKULUKLARI REVİZYON GEREKLİ | T4: 09.10.2026
A5: T-003 | B5: Tank Listesİ | C5: Gümüş Tesisi | D5: 3.0 | E5: FORMALDEHİT TANKI | F5: 201.0 | G5: 270 | H5: FORMALDEHİT | I5: Ayaksız tank | K5: API- 653 | L5: Out of service 10 yıl / İn Service 5 yıl | M5: 2018-07-01 00:00:00 | N5: 2023-07-01 00:00:00 | O5: =IFERROR(IF(N5="","",DATEVALUE(TEXT(N5,"DD.MM.YYYY"))-TODAY()),"Tarih Yok") -> Tarih Yok | P5: =IFERROR(IF(N5="","Tarih Yok",IF(DATEVALUE(TEXT(N5,"DD.MM.YYYY"))<TODAY(),"GECİKMİŞ",IF(DATEVALUE(TEXT(N5,"DD.MM.YYYY"))-TODAY()<=30,"30 GÜN İÇİNDE",IF(DATEVALUE(TEXT(N5,"DD.MM.YYYY"))-TODAY()<=90,"90 GÜN İÇİNDE","Takvimdeyiz")))),"Tarih Kontrol") -> Tarih Kontrol | Q5: Uygun Değil | S5: Sadece inservice raporu bulunmaktadır. Out of sevice raporu da olmalıdır. Bu sebeple uygunsuzdur. | T5: 09.10.2026
A6: T-004 | B6: Tank Listesİ | C6: Gümüş Tesisi | D6: 4.0 | E6: FORMALDEHIT TANKI-2 | F6: 301.0 | G6: 289 | H6: UFC | I6: Ayaksız tank | K6: API- 653 | L6: Out of service 10 yıl / İn Service 5 yıl | M6: 2020-01-01 00:00:00 | N6: 2025-01-01 00:00:00 | O6: =IFERROR(IF(N6="","",DATEVALUE(TEXT(N6,"DD.MM.YYYY"))-TODAY()),"Tarih Yok") -> Tarih Yok | P6: =IFERROR(IF(N6="","Tarih Yok",IF(DATEVALUE(TEXT(N6,"DD.MM.YYYY"))<TODAY(),"GECİKMİŞ",IF(DATEVALUE(TEXT(N6,"DD.MM.YYYY"))-TODAY()<=30,"30 GÜN İÇİNDE",IF(DATEVALUE(TEXT(N6,"DD.MM.YYYY"))-TODAY()<=90,"90 GÜN İÇİNDE","Takvimdeyiz")))),"Tarih Kontrol") -> Tarih Kontrol | Q6: Uygun Değil | S6: Sadece inservice raporu bulunmaktadır. Out of sevice raporu da olmalıdır. Bu sebeple uygunsuzdur. | T6: 09.10.2026
A7: T-005 | B7: Tank Listesİ | C7: Gümüş Tesisi | D7: 5.0 | E7: FORMALDEHIT TANKI-3 | F7: 302.0 | G7: 289 | H7: FORMALDEHİT | I7: Ayaksız tank | K7: API- 653 | L7: Out of service 10 yıl / İn Service 5 yıl | M7: 2018-07-01 00:00:00 | N7: 2023-07-01 00:00:00 | O7: =IFERROR(IF(N7="","",DATEVALUE(TEXT(N7,"DD.MM.YYYY"))-TODAY()),"Tarih Yok") -> Tarih Yok | P7: =IFERROR(IF(N7="","Tarih Yok",IF(DATEVALUE(TEXT(N7,"DD.MM.YYYY"))<TODAY(),"GECİKMİŞ",IF(DATEVALUE(TEXT(N7,"DD.MM.YYYY"))-TODAY()<=30,"30 GÜN İÇİNDE",IF(DATEVALUE(TEXT(N7,"DD.MM.YYYY"))-TODAY()<=90,"90 GÜN İÇİNDE","Takvimdeyiz")))),"Tarih Kontrol") -> Tarih Kontrol | Q7: Uygun Değil | S7: Sadece inservice raporu bulunmaktadır. Out of sevice raporu da olmalıdır. Bu sebeple uygunsuzdur. | T7: 09.10.2026
A8: T-006 | B8: Tank Listesİ | C8: Gümüş Tesisi | D8: 6.0 | E8: FORMALDEHIT TANKI-4 | F8: 501.0 | G8: 510 | H8: UFC | I8: Ayaksız tank | K8: API- 653 | L8: Out of service 10 yıl / İn Service 5 yıl | M8: 2021-03-01 00:00:00 | N8: 2026-03-01 00:00:00 | O8: =IFERROR(IF(N8="","",DATEVALUE(TEXT(N8,"DD.MM.YYYY"))-TODAY()),"Tarih Yok") -> Tarih Yok | P8: =IFERROR(IF(N8="","Tarih Yok",IF(DATEVALUE(TEXT(N8,"DD.MM.YYYY"))<TODAY(),"GECİKMİŞ",IF(DATEVALUE(TEXT(N8,"DD.MM.YYYY"))-TODAY()<=30,"30 GÜN İÇİNDE",IF(DATEVALUE(TEXT(N8,"DD.MM.YYYY"))-TODAY()<=90,"90 GÜN İÇİNDE","Takvimdeyiz")))),"Tarih Kontrol") -> Tarih Kontrol | Q8: Uygun Değil | S8: Sadece inservice raporu bulunmaktadır. Out of sevice raporu da olmalıdır. Bu sebeple uygunsuzdur. | T8: 09.10.2026
A9: T-007 | B9: Tank Listesİ | C9: Gümüş Tesisi | D9: 7.0 | E9: FORMALDEHIT TANKI-5 | F9: 502.0 | G9: 511 | H9: FORMALDEHİT | I9: Ayaksız tank | K9: API- 653 | L9: Out of service 10 yıl / İn Service 5 yıl | M9: 2018-07-01 00:00:00 | N9: 2023-07-01 00:00:00 | O9: =IFERROR(IF(N9="","",DATEVALUE(TEXT(N9,"DD.MM.YYYY"))-TODAY()),"Tarih Yok") -> Tarih Yok | P9: =IFERROR(IF(N9="","Tarih Yok",IF(DATEVALUE(TEXT(N9,"DD.MM.YYYY"))<TODAY(),"GECİKMİŞ",IF(DATEVALUE(TEXT(N9,"DD.MM.YYYY"))-TODAY()<=30,"30 GÜN İÇİNDE",IF(DATEVALUE(TEXT(N9,"DD.MM.YYYY"))-TODAY()<=90,"90 GÜN İÇİNDE","Takvimdeyiz")))),"Tarih Kontrol") -> Tarih Kontrol | Q9: Uygun Değil | S9: Sadece inservice raporu bulunmaktadır. Out of sevice raporu da olmalıdır. Bu sebeple uygunsuzdur. | T9: 09.10.2026
A10: T-008 | B10: Tank Listesİ | C10: Gümüş Tesisi | D10: 8.0 | E10: FORMALDEHIT TANKI-6 | F10: 101.0 | G10: 115 | H10: UFC | I10: Ayaksız tank | K10: API- 653 | L10: Out of service 10 yıl / İn Service 5 yıl | M10: 2018-07-01 00:00:00 | N10: 2023-07-01 00:00:00 | O10: =IFERROR(IF(N10="","",DATEVALUE(TEXT(N10,"DD.MM.YYYY"))-TODAY()),"Tarih Yok") -> Tarih Yok | P10: =IFERROR(IF(N10="","Tarih Yok",IF(DATEVALUE(TEXT(N10,"DD.MM.YYYY"))<TODAY(),"GECİKMİŞ",IF(DATEVALUE(TEXT(N10,"DD.MM.YYYY"))-TODAY()<=30,"30 GÜN İÇİNDE",IF(DATEVALUE(TEXT(N10,"DD.MM.YYYY"))-TODAY()<=90,"90 GÜN İÇİNDE","Takvimdeyiz")))),"Tarih Kontrol") -> Tarih Kontrol | Q10: Uygun Değil | S10: Sadece inservice raporu bulunmaktadır. Out of sevice raporu da olmalıdır. Bu sebeple uygunsuzdur. | T10: 09.10.2026
A11: T-009 | B11: Tank Listesİ | C11: Gümüş Tesisi | D11: 9.0 | E11: FORMALDEHIT TANKI-8 | F11: 300.0 | G11: 100 | H11: UFC | I11: Ayaksız tank | K11: API- 653 | L11: Out of service 10 yıl / İn Service 5 yıl | M11: 2018-07-01 00:00:00 | N11: 2023-07-01 00:00:00 | O11: =IFERROR(IF(N11="","",DATEVALUE(TEXT(N11,"DD.MM.YYYY"))-TODAY()),"Tarih Yok") -> Tarih Yok | P11: =IFERROR(IF(N11="","Tarih Yok",IF(DATEVALUE(TEXT(N11,"DD.MM.YYYY"))<TODAY(),"GECİKMİŞ",IF(DATEVALUE(TEXT(N11,"DD.MM.YYYY"))-TODAY()<=30,"30 GÜN İÇİNDE",IF(DATEVALUE(TEXT(N11,"DD.MM.YYYY"))-TODAY()<=90,"90 GÜN İÇİNDE","Takvimdeyiz")))),"Tarih Kontrol") -> Tarih Kontrol | Q11: Uygun Değil | S11: Sadece inservice raporu bulunmaktadır. Out of sevice raporu da olmalıdır. Bu sebeple uygunsuzdur. | T11: 09.10.2026
A12: T-010 | B12: Tank Listesİ | C12: Gümüş Tesisi | D12: 10.0 | E12: FORMALDEHIT TANKI | F12: 601.0 | G12: 74 | H12: FORMALDEHİT | I12: Ayaklı tank | K12: TS EN 12285 -2 / API- 510 | L12: Yıllık | M12: 2025-04-07 00:00:00 | N12: 2026-04-06 00:00:00 | O12: =IFERROR(IF(N12="","",DATEVALUE(TEXT(N12,"DD.MM.YYYY"))-TODAY()),"Tarih Yok") -> Tarih Yok | P12: =IFERROR(IF(N12="","Tarih Yok",IF(DATEVALUE(TEXT(N12,"DD.MM.YYYY"))<TODAY(),"GECİKMİŞ",IF(DATEVALUE(TEXT(N12,"DD.MM.YYYY"))-TODAY()<=30,"30 GÜN İÇİNDE",IF(DATEVALUE(TEXT(N12,"DD.MM.YYYY"))-TODAY()<=90,"90 GÜN İÇİNDE","Takvimdeyiz")))),"Tarih Kontrol") -> Tarih Kontrol | Q12: Uygun | S12: TAVAN KORKULUKLARI VE ALT SÜPÜRGELİKLERİ YOK. | T12: 09.10.2026
A13: T-011 | B13: Tank Listesİ | C13: Gümüş Tesisi | D13: 11.0 | E13: FENOL TANKI | F13: 702.0 | G13: 119 | H13: FENOL | I13: Ayaksız tank | K13: API- 653 | L13: Out of service 10 yıl / İn Service 5 yıl | M13: 2021-03-01 00:00:00 | O13: =IFERROR(IF(N13="","",DATEVALUE(TEXT(N13,"DD.MM.YYYY"))-TODAY()),"Tarih Yok") | P13: =IFERROR(IF(N13="","Tarih Yok",IF(DATEVALUE(TEXT(N13,"DD.MM.YYYY"))<TODAY(),"GECİKMİŞ",IF(DATEVALUE(TEXT(N13,"DD.MM.YYYY"))-TODAY()<=30,"30 GÜN İÇİNDE",IF(DATEVALUE(TEXT(N13,"DD.MM.YYYY"))-TODAY()<=90,"90 GÜN İÇİNDE","Takvimdeyiz")))),"Tarih Kontrol") -> Tarih Yok | Q13: Uygunsuz | S13: Sadece inservice raporu bulunmaktadır. Out of sevice raporu da olmalıdır. Bu sebeple uygunsuzdur. | T13: 09.10.2026
A14: T-012 | B14: Tank Listesİ | C14: Gümüş Tesisi | D14: 12.0 | E14: METANOL TANKI | F14: 303.0 | G14: 400 | H14: METANOL | I14: Ayaksız tank | K14: API- 653 | L14: Out of service 10 yıl / İn Service 5 yıl | M14: 25.08.2025 API 653 | N14: 2030-08-28 00:00:00 | O14: =IFERROR(IF(N14="","",DATEVALUE(TEXT(N14,"DD.MM.YYYY"))-TODAY()),"Tarih Yok") -> Tarih Yok | P14: =IFERROR(IF(N14="","Tarih Yok",IF(DATEVALUE(TEXT(N14,"DD.MM.YYYY"))<TODAY(),"GECİKMİŞ",IF(DATEVALUE(TEXT(N14,"DD.MM.YYYY"))-TODAY()<=30,"30 GÜN İÇİNDE",IF(DATEVALUE(TEXT(N14,"DD.MM.YYYY"))-TODAY()<=90,"90 GÜN İÇİNDE","Takvimdeyiz")))),"Tarih Kontrol") -> Tarih Kontrol | Q14: Uygun | S14: TANK KOMPLE MEKANİK BAKIMA ALINMALI - KUMLAMA BOYA - KOROZYON OLUŞUMU ÇOK ŞİDDETLİ | T14: 09.10.2026
A15: T-013 | B15: Tank Listesİ | C15: Gümüş Tesisi | D15: 13.0 | E15: DESTİLAT TANKI | F15: 705.0 | G15: 63 | I15: Ayaklı tank | K15: TS EN 12285 -2 / API- 510 | L15: Yıllık | M15: 2025-04-08 00:00:00 | N15: 2026-04-08 00:00:00 | O15: =IFERROR(IF(N15="","",DATEVALUE(TEXT(N15,"DD.MM.YYYY"))-TODAY()),"Tarih Yok") -> Tarih Yok | P15: =IFERROR(IF(N15="","Tarih Yok",IF(DATEVALUE(TEXT(N15,"DD.MM.YYYY"))<TODAY(),"GECİKMİŞ",IF(DATEVALUE(TEXT(N15,"DD.MM.YYYY"))-TODAY()<=30,"30 GÜN İÇİNDE",IF(DATEVALUE(TEXT(N15,"DD.MM.YYYY"))-TODAY()<=90,"90 GÜN İÇİNDE","Takvimdeyiz")))),"Tarih Kontrol") -> Tarih Kontrol | Q15: Uygun | S15: TAVAN KORKULUKLARI VE ALT SÜPÜRGELİKLERİ YOK. | T15: 09.10.2026
A16: T-014 | B16: Tank Listesİ | C16: Gümüş Tesisi | D16: 14.0 | E16: KONDENS TANKI | F16: 704.0 | G16: 13 | I16: Ayaklı tank | K16: TS EN 12285 -2 / API- 510 | L16: Yıllık | M16: 2025-04-01 00:00:00 | O16: =IFERROR(IF(N16="","",DATEVALUE(TEXT(N16,"DD.MM.YYYY"))-TODAY()),"Tarih Yok") | P16: =IFERROR(IF(N16="","Tarih Yok",IF(DATEVALUE(TEXT(N16,"DD.MM.YYYY"))<TODAY(),"GECİKMİŞ",IF(DATEVALUE(TEXT(N16,"DD.MM.YYYY"))-TODAY()<=30,"30 GÜN İÇİNDE",IF(DATEVALUE(TEXT(N16,"DD.MM.YYYY"))-TODAY()<=90,"90 GÜN İÇİNDE","Takvimdeyiz")))),"Tarih Kontrol") -> Tarih Yok | Q16: Uygun Değil | S16: TANK KOROZYON KAYNAKLI INSPECTION YAPILAMAMIŞTIR. KUMLAMA BOYA GEREKLİDİR. | T16: 09.10.2026
A17: T-015 | B17: Tank Listesİ | C17: Gümüş Tesisi | D17: 15.0 | E17: PROSES SU TANKI | F17: 701.0 | G17: 68 | I17: Ayaklı tank | K17: TS EN 12285 -2 / API- 510 | L17: Yıllık | M17: 2025-04-08 00:00:00 | N17: 2026-04-08 00:00:00 | O17: =IFERROR(IF(N17="","",DATEVALUE(TEXT(N17,"DD.MM.YYYY"))-TODAY()),"Tarih Yok") -> Tarih Yok | P17: =IFERROR(IF(N17="","Tarih Yok",IF(DATEVALUE(TEXT(N17,"DD.MM.YYYY"))<TODAY(),"GECİKMİŞ",IF(DATEVALUE(TEXT(N17,"DD.MM.YYYY"))-TODAY()<=30,"30 GÜN İÇİNDE",IF(DATEVALUE(TEXT(N17,"DD.MM.YYYY"))-TODAY()<=90,"90 GÜN İÇİNDE","Takvimdeyiz")))),"Tarih Kontrol") -> Tarih Kontrol | Q17: Uygun | S17: TAVAN KORKULUKLARI VE ALT SÜPÜRGELİKLERİ YOK. | T17: 09.10.2026
A18: T-016 | B18: Tank Listesİ | C18: Gümüş Tesisi | D18: 16.0 | E18: SU TANKI | F18: 102.0 | G18: 115 | I18: Ayaklı tank | K18: TS EN 12285 -2 / API- 510 | L18: Yıllık | M18: 2018-07-01 00:00:00 | O18: =IFERROR(IF(N18="","",DATEVALUE(TEXT(N18,"DD.MM.YYYY"))-TODAY()),"Tarih Yok") | P18: =IFERROR(IF(N18="","Tarih Yok",IF(DATEVALUE(TEXT(N18,"DD.MM.YYYY"))<TODAY(),"GECİKMİŞ",IF(DATEVALUE(TEXT(N18,"DD.MM.YYYY"))-TODAY()<=30,"30 GÜN İÇİNDE",IF(DATEVALUE(TEXT(N18,"DD.MM.YYYY"))-TODAY()<=90,"90 GÜN İÇİNDE","Takvimdeyiz")))),"Tarih Kontrol") -> Tarih Yok | Q18: Kontrolü yok | T18: 09.10.2026
A19: T-017 | B19: Tank Listesİ | C19: Gümüş Tesisi | D19: 17.0 | E19: RECINE TANKI-1 | F19: 1.0 | G19: 115 | H19: ÜRE REÇİNESİ | I19: Ayaklı tank | K19: TS EN 12285 -2 / API- 510 | L19: Yıllık | M19: 2025-03-22 00:00:00 | N19: 2026-03-22 00:00:00 | O19: =IFERROR(IF(N19="","",DATEVALUE(TEXT(N19,"DD.MM.YYYY"))-TODAY()),"Tarih Yok") -> Tarih Yok | P19: =IFERROR(IF(N19="","Tarih Yok",IF(DATEVALUE(TEXT(N19,"DD.MM.YYYY"))<TODAY(),"GECİKMİŞ",IF(DATEVALUE(TEXT(N19,"DD.MM.YYYY"))-TODAY()<=30,"30 GÜN İÇİNDE",IF(DATEVALUE(TEXT(N19,"DD.MM.YYYY"))-TODAY()<=90,"90 GÜN İÇİNDE","Takvimdeyiz")))),"Tarih Kontrol") -> Tarih Kontrol | Q19: Uygun | S19: UYGUN | T19: 09.10.2026
A20: T-018 | B20: Tank Listesİ | C20: Gümüş Tesisi | D20: 18.0 | E20: RECINE TANKI-2 | F20: 2.0 | G20: 115 | H20: ÜRE REÇİNESİ | I20: Ayaklı tank | K20: TS EN 12285 -2 / API- 510 | L20: Yıllık | M20: 2025-03-22 00:00:00 | N20: 2026-03-22 00:00:00 | O20: =IFERROR(IF(N20="","",DATEVALUE(TEXT(N20,"DD.MM.YYYY"))-TODAY()),"Tarih Yok") -> Tarih Yok | P20: =IFERROR(IF(N20="","Tarih Yok",IF(DATEVALUE(TEXT(N20,"DD.MM.YYYY"))<TODAY(),"GECİKMİŞ",IF(DATEVALUE(TEXT(N20,"DD.MM.YYYY"))-TODAY()<=30,"30 GÜN İÇİNDE",IF(DATEVALUE(TEXT(N20,"DD.MM.YYYY"))-TODAY()<=90,"90 GÜN İÇİNDE","Takvimdeyiz")))),"Tarih Kontrol") -> Tarih Kontrol | Q20: Uygun | S20: UYGUN | T20: 09.10.2026
A21: T-019 | B21: Tank Listesİ | C21: Gümüş Tesisi | D21: 19.0 | E21: RECINE TANKI-3 | F21: 3.0 | G21: 115 | H21: ÜRE REÇİNESİ | I21: Ayaklı tank | K21: TS EN 12285 -2 / API- 510 | L21: Yıllık | M21: 2025-03-22 00:00:00 | N21: 2026-03-22 00:00:00 | O21: =IFERROR(IF(N21="","",DATEVALUE(TEXT(N21,"DD.MM.YYYY"))-TODAY()),"Tarih Yok") -> Tarih Yok | P21: =IFERROR(IF(N21="","Tarih Yok",IF(DATEVALUE(TEXT(N21,"DD.MM.YYYY"))<TODAY(),"GECİKMİŞ",IF(DATEVALUE(TEXT(N21,"DD.MM.YYYY"))-TODAY()<=30,"30 GÜN İÇİNDE",IF(DATEVALUE(TEXT(N21,"DD.MM.YYYY"))-TODAY()<=90,"90 GÜN İÇİNDE","Takvimdeyiz")))),"Tarih Kontrol") -> Tarih Kontrol | Q21: Uygun | S21: UYGUN | T21: 09.10.2026
A22: T-020 | B22: Tank Listesİ | C22: Gümüş Tesisi | D22: 20.0 | E22: RECINE TANKI-4 | F22: 4.0 | G22: 115 | H22: ÜRE REÇİNESİ | I22: Ayaklı tank | K22: TS EN 12285 -2 / API- 510 | L22: Yıllık | M22: 2025-03-22 00:00:00 | N22: 2026-03-22 00:00:00 | O22: =IFERROR(IF(N22="","",DATEVALUE(TEXT(N22,"DD.MM.YYYY"))-TODAY()),"Tarih Yok") -> Tarih Yok | P22: =IFERROR(IF(N22="","Tarih Yok",IF(DATEVALUE(TEXT(N22,"DD.MM.YYYY"))<TODAY(),"GECİKMİŞ",IF(DATEVALUE(TEXT(N22,"DD.MM.YYYY"))-TODAY()<=30,"30 GÜN İÇİNDE",IF(DATEVALUE(TEXT(N22,"DD.MM.YYYY"))-TODAY()<=90,"90 GÜN İÇİNDE","Takvimdeyiz")))),"Tarih Kontrol") -> Tarih Kontrol | Q22: Uygun | S22: UYGUN | T22: 09.10.2026
A23: T-021 | B23: Tank Listesİ | C23: Gümüş Tesisi | D23: 21.0 | E23: RECINE TANKI-5 | F23: 5.0 | G23: 115 | H23: ÜRE REÇİNESİ | I23: Ayaklı tank | K23: TS EN 12285 -2 / API- 510 | L23: Yıllık | M23: 2025-03-22 00:00:00 | N23: 2026-03-22 00:00:00 | O23: =IFERROR(IF(N23="","",DATEVALUE(TEXT(N23,"DD.MM.YYYY"))-TODAY()),"Tarih Yok") -> Tarih Yok | P23: =IFERROR(IF(N23="","Tarih Yok",IF(DATEVALUE(TEXT(N23,"DD.MM.YYYY"))<TODAY(),"GECİKMİŞ",IF(DATEVALUE(TEXT(N23,"DD.MM.YYYY"))-TODAY()<=30,"30 GÜN İÇİNDE",IF(DATEVALUE(TEXT(N23,"DD.MM.YYYY"))-TODAY()<=90,"90 GÜN İÇİNDE","Takvimdeyiz")))),"Tarih Kontrol") -> Tarih Kontrol | Q23: Uygun | S23: UYGUN | T23: 09.10.2026
A24: T-022 | B24: Tank Listesİ | C24: Gümüş Tesisi | D24: 22.0 | E24: RECINE TANKI-8 | F24: 8.0 | G24: 115 | H24: ÜRE REÇİNESİ | I24: Ayaklı tank | K24: TS EN 12285 -2 / API- 510 | L24: Yıllık | M24: 2025-03-22 00:00:00 | N24: 2026-03-22 00:00:00 | O24: =IFERROR(IF(N24="","",DATEVALUE(TEXT(N24,"DD.MM.YYYY"))-TODAY()),"Tarih Yok") -> Tarih Yok | P24: =IFERROR(IF(N24="","Tarih Yok",IF(DATEVALUE(TEXT(N24,"DD.MM.YYYY"))<TODAY(),"GECİKMİŞ",IF(DATEVALUE(TEXT(N24,"DD.MM.YYYY"))-TODAY()<=30,"30 GÜN İÇİNDE",IF(DATEVALUE(TEXT(N24,"DD.MM.YYYY"))-TODAY()<=90,"90 GÜN İÇİNDE","Takvimdeyiz")))),"Tarih Kontrol") -> Tarih Kontrol | Q24: Uygun | S24: UYGUN | T24: 09.10.2026
A25: T-023 | B25: Tank Listesİ | C25: Gümüş Tesisi | D25: 23.0 | E25: RECINE TANKI-9 | F25: 9.0 | G25: 115 | H25: ÜRE REÇİNESİ | I25: Ayaklı tank | K25: TS EN 12285 -2 / API- 510 | L25: Yıllık | M25: 2025-03-22 00:00:00 | N25: 2026-03-22 00:00:00 | O25: =IFERROR(IF(N25="","",DATEVALUE(TEXT(N25,"DD.MM.YYYY"))-TODAY()),"Tarih Yok") -> Tarih Yok | P25: =IFERROR(IF(N25="","Tarih Yok",IF(DATEVALUE(TEXT(N25,"DD.MM.YYYY"))<TODAY(),"GECİKMİŞ",IF(DATEVALUE(TEXT(N25,"DD.MM.YYYY"))-TODAY()<=30,"30 GÜN İÇİNDE",IF(DATEVALUE(TEXT(N25,"DD.MM.YYYY"))-TODAY()<=90,"90 GÜN İÇİNDE","Takvimdeyiz")))),"Tarih Kontrol") -> Tarih Kontrol | Q25: Uygun | S25: UYGUN | T25: 09.10.2026
A26: T-024 | B26: Tank Listesİ | C26: Gümüş Tesisi | D26: 24.0 | E26: RECINE TANKI-10 | F26: 10.0 | G26: 115 | H26: ÜRE REÇİNESİ | I26: Ayaklı tank | K26: TS EN 12285 -2 / API- 510 | L26: Yıllık | M26: 2025-03-22 00:00:00 | N26: 2026-03-22 00:00:00 | O26: =IFERROR(IF(N26="","",DATEVALUE(TEXT(N26,"DD.MM.YYYY"))-TODAY()),"Tarih Yok") -> Tarih Yok | P26: =IFERROR(IF(N26="","Tarih Yok",IF(DATEVALUE(TEXT(N26,"DD.MM.YYYY"))<TODAY(),"GECİKMİŞ",IF(DATEVALUE(TEXT(N26,"DD.MM.YYYY"))-TODAY()<=30,"30 GÜN İÇİNDE",IF(DATEVALUE(TEXT(N26,"DD.MM.YYYY"))-TODAY()<=90,"90 GÜN İÇİNDE","Takvimdeyiz")))),"Tarih Kontrol") -> Tarih Kontrol | Q26: Uygun | S26: UYGUN | T26: 09.10.2026
A27: T-025 | B27: Tank Listesİ | C27: Gümüş Tesisi | D27: 25.0 | E27: RECINE TANKI-6 | F27: 6.0 | G27: 67 | H27: ÜRE REÇİNESİ | I27: Ayaklı tank | K27: TS EN 12285 -2 / API- 510 | L27: Yıllık | M27: 2025-03-22 00:00:00 | N27: 2026-03-22 00:00:00 | O27: =IFERROR(IF(N27="","",DATEVALUE(TEXT(N27,"DD.MM.YYYY"))-TODAY()),"Tarih Yok") -> Tarih Yok | P27: =IFERROR(IF(N27="","Tarih Yok",IF(DATEVALUE(TEXT(N27,"DD.MM.YYYY"))<TODAY(),"GECİKMİŞ",IF(DATEVALUE(TEXT(N27,"DD.MM.YYYY"))-TODAY()<=30,"30 GÜN İÇİNDE",IF(DATEVALUE(TEXT(N27,"DD.MM.YYYY"))-TODAY()<=90,"90 GÜN İÇİNDE","Takvimdeyiz")))),"Tarih Kontrol") -> Tarih Kontrol | Q27: Uygun | S27: UYGUN | T27: 09.10.2026
A28: T-026 | B28: Tank Listesİ | C28: Gümüş Tesisi | D28: 26.0 | E28: RECINE TANKI-7 | F28: 7.0 | G28: 67 | H28: ÜRE REÇİNESİ | I28: Ayaklı tank | K28: TS EN 12285 -2 / API- 510 | L28: Yıllık | M28: 2025-03-22 00:00:00 | N28: 2026-03-22 00:00:00 | O28: =IFERROR(IF(N28="","",DATEVALUE(TEXT(N28,"DD.MM.YYYY"))-TODAY()),"Tarih Yok") -> Tarih Yok | P28: =IFERROR(IF(N28="","Tarih Yok",IF(DATEVALUE(TEXT(N28,"DD.MM.YYYY"))<TODAY(),"GECİKMİŞ",IF(DATEVALUE(TEXT(N28,"DD.MM.YYYY"))-TODAY()<=30,"30 GÜN İÇİNDE",IF(DATEVALUE(TEXT(N28,"DD.MM.YYYY"))-TODAY()<=90,"90 GÜN İÇİNDE","Takvimdeyiz")))),"Tarih Kontrol") -> Tarih Kontrol | Q28: Uygun | S28: UYGUN | T28: 09.10.2026
A29: T-027 | B29: Tank Listesİ | C29: Gümüş Tesisi | D29: 27.0 | E29: FENOL FORMALDEHIT TANKI-11 | F29: 11.0 | G29: 53 | H29: FENOL REÇİNE | I29: Ayaksız tank | K29: TS EN 12285 -2 / API- 510 | L29: Out of service 10 yıl / İn Service 5 yıl | M29: 2025-03-28 00:00:00 | N29: 2030-03-27 00:00:00 | O29: =IFERROR(IF(N29="","",DATEVALUE(TEXT(N29,"DD.MM.YYYY"))-TODAY()),"Tarih Yok") -> Tarih Yok | P29: =IFERROR(IF(N29="","Tarih Yok",IF(DATEVALUE(TEXT(N29,"DD.MM.YYYY"))<TODAY(),"GECİKMİŞ",IF(DATEVALUE(TEXT(N29,"DD.MM.YYYY"))-TODAY()<=30,"30 GÜN İÇİNDE",IF(DATEVALUE(TEXT(N29,"DD.MM.YYYY"))-TODAY()<=90,"90 GÜN İÇİNDE","Takvimdeyiz")))),"Tarih Kontrol") -> Tarih Kontrol | Q29: Uygun | S29: UYGUN | T29: 09.10.2026
A30: T-028 | B30: Tank Listesİ | C30: Gümüş Tesisi | D30: 28.0 | E30: FENOL FORMALDEHIT TANKI-12 | F30: 12.0 | G30: 53 | H30: FENOL REÇİNE | I30: Ayaksız tank | K30: TS EN 12285 -2 / API- 510 | L30: Out of service 10 yıl / İn Service 5 yıl | M30: 2025-03-28 00:00:00 | N30: 2030-03-27 00:00:00 | O30: =IFERROR(IF(N30="","",DATEVALUE(TEXT(N30,"DD.MM.YYYY"))-TODAY()),"Tarih Yok") -> Tarih Yok | P30: =IFERROR(IF(N30="","Tarih Yok",IF(DATEVALUE(TEXT(N30,"DD.MM.YYYY"))<TODAY(),"GECİKMİŞ",IF(DATEVALUE(TEXT(N30,"DD.MM.YYYY"))-TODAY()<=30,"30 GÜN İÇİNDE",IF(DATEVALUE(TEXT(N30,"DD.MM.YYYY"))-TODAY()<=90,"90 GÜN İÇİNDE","Takvimdeyiz")))),"Tarih Kontrol") -> Tarih Kontrol | Q30: Uygun | S30: UYGUN | T30: 09.10.2026
... A33: T-031 | B33: Tank Listesİ | C33: Gümüş Tesisi | D33: 31.0 | E33: ALX TANKI | F33: 15.0 | G33: 20 | H33: ÜRE REÇİNESİ | I33: Ayaklı tank | K33: TS EN 12285 -2 / API- 510 | L33: Yıllık | M33: 2025-09-03 00:00:00 | N33: 2026-09-03 00:00:00 | O33: =IFERROR(IF(N33="","",DATEVALUE(TEXT(N33,"DD.MM.YYYY"))-TODAY()),"Tarih Yok") -> Tarih Yok | P33: =IFERROR(IF(N33="","Tarih Yok",IF(DATEVALUE(TEXT(N33,"DD.MM.YYYY"))<TODAY(),"GECİKMİŞ",IF(DATEVALUE(TEXT(N33,"DD.MM.YYYY"))-TODAY()<=30,"30 GÜN İÇİNDE",IF(DATEVALUE(TEXT(N33,"DD.MM.YYYY"))-TODAY()<=90,"90 GÜN İÇİNDE","Takvimdeyiz")))),"Tarih Kontrol") -> Tarih Kontrol | Q33: Kullanım Dışı /Uygun | S33: ANKRAJ VE KORKULUKLARA BAKIM ONARIM VE KUMLAMA BOYA GEREKLİDİR. | T33: 09.10.2026
A34: T-032 | B34: Tank Listesİ | C34: Gümüş Tesisi | D34: 32.0 | E34: AFS TANKI | G34: 23 | H34: AFS | I34: Ayaklı tank | K34: TS EN 12285 -2 / API- 510 | L34: Yıllık | M34: 2025-09-03 00:00:00 | N34: 2026-08-28 00:00:00 | O34: =IFERROR(IF(N34="","",DATEVALUE(TEXT(N34,"DD.MM.YYYY"))-TODAY()),"Tarih Yok") -> Tarih Yok | P34: =IFERROR(IF(N34="","Tarih Yok",IF(DATEVALUE(TEXT(N34,"DD.MM.YYYY"))<TODAY(),"GECİKMİŞ",IF(DATEVALUE(TEXT(N34,"DD.MM.YYYY"))-TODAY()<=30,"30 GÜN İÇİNDE",IF(DATEVALUE(TEXT(N34,"DD.MM.YYYY"))-TODAY()<=90,"90 GÜN İÇİNDE","Takvimdeyiz")))),"Tarih Kontrol") -> Tarih Kontrol | Q34: Uygun | S34: UYGUN | T34: 09.10.2026
A35: T-033 | B35: Tank Listesİ | C35: Gümüş Tesisi | D35: 33.0 | E35: ADBLUE-1 (AUS 32) | F35: 1.0 | G35: 60 | H35: ADBLUE(AUS 32) | I35: Ayaksız tank | K35: TS EN 12285 -2 / API- 510 | L35: Yıllık | M35: 25.08.2025 API 653 | N35: 2030-08-28 00:00:00 | O35: =IFERROR(IF(N35="","",DATEVALUE(TEXT(N35,"DD.MM.YYYY"))-TODAY()),"Tarih Yok") -> Tarih Yok | P35: =IFERROR(IF(N35="","Tarih Yok",IF(DATEVALUE(TEXT(N35,"DD.MM.YYYY"))<TODAY(),"GECİKMİŞ",IF(DATEVALUE(TEXT(N35,"DD.MM.YYYY"))-TODAY()<=30,"30 GÜN İÇİNDE",IF(DATEVALUE(TEXT(N35,"DD.MM.YYYY"))-TODAY()<=90,"90 GÜN İÇİNDE","Takvimdeyiz")))),"Tarih Kontrol") -> Tarih Kontrol | Q35: Uygun | S35: TANK KORKULUK VE MERDİVENLER KUMLAMA BOYA YAPILMASI GEREKLİ | T35: 09.10.2026
A36: T-034 | B36: Tank Listesİ | C36: Gümüş Tesisi | D36: 34.0 | E36: ADBLUE-2 (AUS 32) | F36: 2.0 | G36: 60 | H36: ADBLUE(AUS 32) | I36: Ayaksız tank | K36: TS EN 12285 -2 / API- 510 | L36: Yıllık | M36: 25.08.2025 API 653 | N36: 2030-08-28 00:00:00 | O36: =IFERROR(IF(N36="","",DATEVALUE(TEXT(N36,"DD.MM.YYYY"))-TODAY()),"Tarih Yok") -> Tarih Yok | P36: =IFERROR(IF(N36="","Tarih Yok",IF(DATEVALUE(TEXT(N36,"DD.MM.YYYY"))<TODAY(),"GECİKMİŞ",IF(DATEVALUE(TEXT(N36,"DD.MM.YYYY"))-TODAY()<=30,"30 GÜN İÇİNDE",IF(DATEVALUE(TEXT(N36,"DD.MM.YYYY"))-TODAY()<=90,"90 GÜN İÇİNDE","Takvimdeyiz")))),"Tarih Kontrol") -> Tarih Kontrol | Q36: Uygun | S36: TANK KORKULUK VE MERDİVENLER KUMLAMA BOYA YAPILMASI GEREKLİ | T36: 09.10.2026
A37: T-035 | B37: Tank Listesİ | C37: Gümüş Tesisi | D37: 35.0 | E37: HAMMADDE TANKI -1 ST 70 m3 | F37: 1.0 | G37: 75 | H37: SODYUM LİGNİN LİKİT KİMYA | I37: Ayaksız tank | K37: API 653 | L37: Out of service 10 yıl / İn Service 5 yıl | M37: 16.04.2025 API 653 | N37: 2030-04-15 00:00:00 | O37: =IFERROR(IF(N37="","",DATEVALUE(TEXT(N37,"DD.MM.YYYY"))-TODAY()),"Tarih Yok") -> Tarih Yok | P37: =IFERROR(IF(N37="","Tarih Yok",IF(DATEVALUE(TEXT(N37,"DD.MM.YYYY"))<TODAY(),"GECİKMİŞ",IF(DATEVALUE(TEXT(N37,"DD.MM.YYYY"))-TODAY()<=30,"30 GÜN İÇİNDE",IF(DATEVALUE(TEXT(N37,"DD.MM.YYYY"))-TODAY()<=90,"90 GÜN İÇİNDE","Takvimdeyiz")))),"Tarih Kontrol") -> Tarih Kontrol | Q37: Uygun | S37: MENHOL KUMLAMA BOYA + TAVAN KORKULUKLARI VE ALT SÜPÜRGELİKLERİ YOK. | T37: 09.10.2026
A38: T-036 | B38: Tank Listesİ | C38: Gümüş Tesisi | D38: 36.0 | E38: HAMMADDE TANKI -2 ST 70 m3 | F38: 2.0 | G38: 75 | H38: SODYUM LİGNİN LİKİT KİMYA | I38: Ayaksız tank | K38: API 653 | L38: Out of service 10 yıl / İn Service 5 yıl | M38: 16.04.2025 API 653 | N38: 2030-04-15 00:00:00 | O38: =IFERROR(IF(N38="","",DATEVALUE(TEXT(N38,"DD.MM.YYYY"))-TODAY()),"Tarih Yok") -> Tarih Yok | P38: =IFERROR(IF(N38="","Tarih Yok",IF(DATEVALUE(TEXT(N38,"DD.MM.YYYY"))<TODAY(),"GECİKMİŞ",IF(DATEVALUE(TEXT(N38,"DD.MM.YYYY"))-TODAY()<=30,"30 GÜN İÇİNDE",IF(DATEVALUE(TEXT(N38,"DD.MM.YYYY"))-TODAY()<=90,"90 GÜN İÇİNDE","Takvimdeyiz")))),"Tarih Kontrol") -> Tarih Kontrol | Q38: Uygun | S38: TAVAN KORKULUKLARI VE ALT SÜPÜRGELİKLERİ YOK. | T38: 09.10.2026
A39: T-037 | B39: Tank Listesİ | C39: Gümüş Tesisi | D39: 37.0 | E39: HAMMADDE TANKI -3 ST 70 m3 | F39: 3.0 | G39: 75 | H39: KALSİYUM LİGNİN %50 | I39: Ayaksız tank | K39: API 653 | L39: Out of service 10 yıl / İn Service 5 yıl | M39: 16.04.2025 API 653 | N39: 2030-04-15 00:00:00 | O39: =IFERROR(IF(N39="","",DATEVALUE(TEXT(N39,"DD.MM.YYYY"))-TODAY()),"Tarih Yok") -> Tarih Yok | P39: =IFERROR(IF(N39="","Tarih Yok",IF(DATEVALUE(TEXT(N39,"DD.MM.YYYY"))<TODAY(),"GECİKMİŞ",IF(DATEVALUE(TEXT(N39,"DD.MM.YYYY"))-TODAY()<=30,"30 GÜN İÇİNDE",IF(DATEVALUE(TEXT(N39,"DD.MM.YYYY"))-TODAY()<=90,"90 GÜN İÇİNDE","Takvimdeyiz")))),"Tarih Kontrol") -> Tarih Kontrol | Q39: Uygun | S39: TAVAN KORKULUKLARI VE ALT SÜPÜRGELİKLERİ YOK. | T39: 09.10.2026
A40: T-038 | B40: Tank Listesİ | C40: Gümüş Tesisi | D40: 38.0 | E40: HAMMADDE TANKI -4 ST 70 m3 | F40: 4.0 | G40: 75 | H40: SODYUM LİGNİN LİKİT KİMYA | I40: Ayaksız tank | K40: API 653 | L40: Out of service 10 yıl / İn Service 5 yıl | M40: 16.04.2025 API 653 | N40: 2030-04-15 00:00:00 | O40: =IFERROR(IF(N40="","",DATEVALUE(TEXT(N40,"DD.MM.YYYY"))-TODAY()),"Tarih Yok") -> Tarih Yok | P40: =IFERROR(IF(N40="","Tarih Yok",IF(DATEVALUE(TEXT(N40,"DD.MM.YYYY"))<TODAY(),"GECİKMİŞ",IF(DATEVALUE(TEXT(N40,"DD.MM.YYYY"))-TODAY()<=30,"30 GÜN İÇİNDE",IF(DATEVALUE(TEXT(N40,"DD.MM.YYYY"))-TODAY()<=90,"90 GÜN İÇİNDE","Takvimdeyiz")))),"Tarih Kontrol") -> Tarih Kontrol | Q40: Uygun | S40: TAVAN KORKULUKLARI VE ALT SÜPÜRGELİKLERİ YOK. | T40: 09.10.2026
A41: T-039 | B41: Tank Listesİ | C41: Gümüş Tesisi | D41: 39.0 | E41: HAMMADDE TANKI -11 ST 55 m3 | F41: 11.0 | G41: 61.5 | H41: SODYUM NAFTALİN MKS | I41: Ayaklı tank | K41: TS EN 12285 -2 / API- 510 | L41: Yıllık | M41: 2025-04-01 00:00:00 | N41: 2026-04-14 00:00:00 | O41: =IFERROR(IF(N41="","",DATEVALUE(TEXT(N41,"DD.MM.YYYY"))-TODAY()),"Tarih Yok") -> Tarih Yok | P41: =IFERROR(IF(N41="","Tarih Yok",IF(DATEVALUE(TEXT(N41,"DD.MM.YYYY"))<TODAY(),"GECİKMİŞ",IF(DATEVALUE(TEXT(N41,"DD.MM.YYYY"))-TODAY()<=30,"30 GÜN İÇİNDE",IF(DATEVALUE(TEXT(N41,"DD.MM.YYYY"))-TODAY()<=90,"90 GÜN İÇİNDE","Takvimdeyiz")))),"Tarih Kontrol") -> Tarih Kontrol | Q41: Uygun | S41: TAVAN KORKULUKLARI VE ALT SÜPÜRGELİKLERİ YOK. | T41: 09.10.2026
A42: T-040 | B42: Tank Listesİ | C42: Gümüş Tesisi | D42: 40.0 | E42: HAMMADDE TANKI -12 ST 55 m3 | F42: 12.0 | G42: 61.5 | H42: TIPA | I42: Ayaklı tank | K42: TS EN 12285 -2 / API- 510 | L42: Yıllık | M42: 2025-04-01 00:00:00 | N42: 2026-04-14 00:00:00 | O42: =IFERROR(IF(N42="","",DATEVALUE(TEXT(N42,"DD.MM.YYYY"))-TODAY()),"Tarih Yok") -> Tarih Yok | P42: =IFERROR(IF(N42="","Tarih Yok",IF(DATEVALUE(TEXT(N42,"DD.MM.YYYY"))<TODAY(),"GECİKMİŞ",IF(DATEVALUE(TEXT(N42,"DD.MM.YYYY"))-TODAY()<=30,"30 GÜN İÇİNDE",IF(DATEVALUE(TEXT(N42,"DD.MM.YYYY"))-TODAY()<=90,"90 GÜN İÇİNDE","Takvimdeyiz")))),"Tarih Kontrol") -> Tarih Kontrol | Q42: Uygun | S42: TAVAN KORKULUKLARI VE ALT SÜPÜRGELİKLERİ YOK. | T42: 09.10.2026
...

Sheet Tank_Muayene_Log
A1: TANK MUAYENİ VE KONTROL KAYIT DEFTERİ
A2: LOG_ID | B2: TANK_ID | C2: Tank_Adı | D2: Muayene_Tarihi | E2: Muayene_Türü | F2: Muayene_Kurulusu | G2: Rapor_No | H2: Bulgular | I2: Önerilen_Aksiyonlar | J2: Bir_Sonraki_Tarih | K2: Durum | L2: Maliyet_TL | M2: İlgili_PRJ | N2: Notlar
A3: LOG-001 | B3: T-012 | C3: METANOL TANKI (303) | D3: 25.08.2025 | E3: API 653 Out-of-Service | F3: Akredite Muayene Firması | H3: Tank komple mekanik bakıma alınmalı; kumlama-boya; korozyon oluşumu çok şiddetli | I3: Kumlama boya yaptırılacak; korozyon derinlik ölçümü | J3: 28.08.2030 | K3: Tamamlandı
A4: LOG-002 | B4: T-033 | C4: ADBLUE-1 (AUS 32) | D4: 25.08.2025 | E4: API 653 | F4: Akredite Muayene Firması | H4: Korkuluk ve merdivenler kumlama boya yapılması gerekli | I4: Korkuluk kumlama boya | J4: 28.08.2030 | K4: Tamamlandı
A5: LOG-003 | B5: T-001 | C5: ANA KOSTİK TANKI (st61m3) | D5: 24.03.2025 | E5: Yıllık Kontrol | F5: Akredite Muayene Firması | H5: Uygun | J5: 24.03.2026 | K5: Tamamlandı

Sheet Dolum_Hortumlari
A1: DOLUM HORTUMLARI VE TRANSFER EKİPMANLARI
A2: HORTUM_ID | B2: Etiket/Seri_No | C2: Tesis | D2: Dolum_Noktası | E2: Kimyasal | F2: Hortum_Tipi | G2: İç_Malzeme | H2: Dış_Malzeme | I2: Çap_mm | J2: Uzunluk_m | K2: Bağlantı_Tipi | L2: Basınç_Sınıfı_bar | M2: Kim_Uyumluluk | N2: Üretici | O2: Üretim_Tarihi | P2: Devreye_Tarihi | Q2: Son_Kontrol | R2: Sonraki_Kontrol | S2: Durum | T2: Hasar_Kaydı | U2: Son_Değişim_Tarihi | V2: Notlar
A3: Bu sayfa boş şablon olarak sunulmuştur. Gerçek hortum verilerini aşağıya giriniz.

Sheet Ekipman_Envanteri
A1: EKİPMAN ENVANTERİ
A2: EKP_ID | B2: Ekipman_Kodu | C2: Ekipman_Adı | D2: Ekipman_Tipi | E2: Tesis | F2: Sistem | G2: Üretici | H2: Model | I2: Seri_No | J2: Teknik_Özellikler | K2: Son_Bakım | L2: Sonraki_Bakım | M2: Bakım_Sıklığı | N2: Durum | O2: Açık_Bakım_Bildirimleri | P2: Bakım_Maliyet_TL | Q2: İlgili_PRJ | R2: Doküman_Linki
A3: Bu sayfa boş şablon olarak sunulmuştur. SAP ekipman numaralarını koruyarak verilerinizi giriniz.

Sheet Bakim_Gecmisi
A1: BAKIM VE ONARIM GEÇMİŞİ
A2: BAK_ID | B2: EKP_ID | C2: Ekipman_Adı | D2: TANK_ID | E2: Tank_Adı | F2: Bakım_Tarihi | G2: Bakım_Türü | H2: Yapan / Firma | I2: Açıklama | J2: Maliyet_TL | K2: İş_Emri_No | L2: Notlar

Sheet Butce_Maliyet
A1: BÜTÇE, MALİYET VE FİNANSAL TAKİP
A2: Kaynak: SAP Fatura Bazlı Detay — Ocak-Mart 2025 gerçekleşen giderler
A3: KAY_ID | B3: Masraf_Yeri_Kodu | C3: Masraf_Yeri_Adı | D3: Ana_Hesap_Kodu | E3: Gider_Kategorisi | F3: Tutar_TRY | G3: Para_Birimi | H3: Belge_No | I3: Kayıt_Tarihi | J3: Belge_Tarihi | K3: Metin | L3: Kullanıcı | M3: Satıcı_Adı | N3: Sipariş_No | O3: Sipariş_Adı | P3: PRJ_ID
A4: KAY-0001 | B4: 2273020004 | C4: ALT YAPI HIZMETLERI | D4: 7300003001 | E4: YAKITLAR | F4: 2928.24 | G4: TRY | H4: 7532 | I4: 2025-01-31 00:00:00 | J4: 2025-01-31 00:00:00 | K4: 930-T14 | L4: SKIZILTAS | N4: A-34ZB611 | O4: ALT YAPI HIZMETLERI
A5: KAY-0002 | B5: 2273020007 | C5: KAZAN DAIRESI | D5: 7300003001 | E5: YAKITLAR | F5: 214768.86 | G5: TRY | H5: 18892 | I5: 2025-02-28 00:00:00 | J5: 2025-02-28 00:00:00 | K5: 930-T14 | L5: SKIZILTAS
A6: KAY-0003 | B6: 2273020007 | C6: KAZAN DAIRESI | D6: 7300003001 | E6: YAKITLAR | F6: 117129.4 | G6: TRY | H6: 7534 | I6: 2025-01-31 00:00:00 | J6: 2025-01-31 00:00:00 | K6: 930-T14 | L6: SKIZILTAS
A7: KAY-0004 | B7: 2273020004 | C7: ALT YAPI HIZMETLERI | D7: 7300003001 | E7: YAKITLAR | F7: 3536.15 | G7: TRY | H7: 18890 | I7: 2025-02-28 00:00:00 | J7: 2025-02-28 00:00:00 | K7: 930-T14 | L7: SKIZILTAS | N7: A-34ZB611 | O7: ALT YAPI HIZMETLERI
A8: KAY-0005 | B8: 2273020007 | C8: KAZAN DAIRESI | D8: 7300003002 | E8: DOĞALGAZ GİDERİ | F8: 3690972.6 | G8: TRY | H8: 20346 | I8: 2025-02-28 00:00:00 | J8: 2025-02-28 00:00:00 | K8: PLG2025000021122 | L8: SDEMIRTAS | M8: PALGAZ DOĞAL GAZ DAĞITIM SAN.VE TİC
A9: KAY-0006 | B9: 2273020007 | C9: KAZAN DAIRESI | D9: 7300003002 | E9: DOĞALGAZ GİDERİ | F9: 2802197.7 | G9: TRY | H9: 8761 | I9: 2025-01-31 00:00:00 | J9: 2025-01-31 00:00:00 | K9: PLG2025000009875 | L9: SDEMIRTAS | M9: PALGAZ DOĞAL GAZ DAĞITIM SAN.VE TİC
A10: KAY-0007 | B10: 2273020005 | C10: KOMPRESOR HIZMETLERI | D10: 7300003003 | E10: ELEKTRIK SARFI | F10: 24149.49 | G10: TRY | H10: 1000000182 | I10: 2025-02-14 00:00:00 | J10: 2025-02-14 00:00:00 | L10: SDURSUN
A11: KAY-0008 | B11: 2273020005 | C11: KOMPRESOR HIZMETLERI | D11: 7300003003 | E11: ELEKTRIK SARFI | F11: -24149.49 | G11: TRY | H11: 15824 | I11: 2025-02-14 00:00:00 | J11: 2025-02-14 00:00:00 | L11: SDURSUN
A12: KAY-0009 | B12: 2273020006 | C12: JENERATOR HIZMETLERI | D12: 7300003003 | E12: ELEKTRIK SARFI | F12: 3900.58 | G12: TRY | H12: 20373 | I12: 2025-02-28 00:00:00 | J12: 2025-02-28 00:00:00 | L12: SDURSUN
A13: KAY-0010 | B13: 2273020008 | C13: SU ARITMA | D13: 7300003003 | E13: ELEKTRIK SARFI | F13: -893.91 | G13: TRY | H13: 15824 | I13: 2025-02-14 00:00:00 | J13: 2025-02-14 00:00:00 | L13: SDURSUN
A14: KAY-0011 | B14: 2273020007 | C14: KAZAN DAIRESI | D14: 7300003003 | E14: ELEKTRIK SARFI | F14: 117214.11 | G14: TRY | H14: 20373 | I14: 2025-02-28 00:00:00 | J14: 2025-02-28 00:00:00 | L14: SDURSUN
A15: KAY-0012 | B15: 2273020006 | C15: JENERATOR HIZMETLERI | D15: 7300003003 | E15: ELEKTRIK SARFI | F15: -243.94 | G15: TRY | H15: 15824 | I15: 2025-02-14 00:00:00 | J15: 2025-02-14 00:00:00 | L15: SDURSUN
A16: KAY-0013 | B16: 2272000003 | C16: SU URETIM | D16: 7300003003 | E16: ELEKTRIK SARFI | F16: -14754.82 | G16: TRY | H16: 15824 | I16: 2025-02-14 00:00:00 | J16: 2025-02-14 00:00:00 | L16: SDURSUN
A17: KAY-0014 | B17: 2273020008 | C17: SU ARITMA | D17: 7300003003 | E17: ELEKTRIK SARFI | F17: 13690.71 | G17: TRY | H17: 8840 | I17: 2025-01-31 00:00:00 | J17: 2025-01-31 00:00:00 | L17: SDURSUN
A18: KAY-0015 | B18: 2273020004 | C18: ALT YAPI HIZMETLERI | D18: 7300003003 | E18: ELEKTRIK SARFI | F18: 84741.13 | G18: TRY | H18: 20373 | I18: 2025-02-28 00:00:00 | J18: 2025-02-28 00:00:00 | L18: SDURSUN
A19: KAY-0016 | B19: 2272000003 | C19: SU URETIM | D19: 7300003003 | E19: ELEKTRIK SARFI | F19: -14754.82 | G19: TRY | H19: 15830 | I19: 2025-02-14 00:00:00 | J19: 2025-02-14 00:00:00 | L19: SDURSUN
A20: KAY-0017 | B20: 2273020003 | C20: TEKNIK ORTAK HIZMETL | D20: 7300003003 | E20: ELEKTRIK SARFI | F20: 961682.59 | G20: TRY | H20: 8840 | I20: 2025-01-31 00:00:00 | J20: 2025-01-31 00:00:00 | L20: SDURSUN
A21: KAY-0018 | B21: 2273020006 | C21: JENERATOR HIZMETLERI | D21: 7300003003 | E21: ELEKTRIK SARFI | F21: 3735.99 | G21: TRY | H21: 8840 | I21: 2025-01-31 00:00:00 | J21: 2025-01-31 00:00:00 | L21: SDURSUN
... A44: KAY-0041 | B44: 2272000003 | C44: SU URETIM | D44: 7300003003 | E44: ELEKTRIK SARFI | F44: 224481.25 | G44: TRY | H44: 20373 | I44: 2025-02-28 00:00:00 | J44: 2025-02-28 00:00:00 | L44: SDURSUN
A45: KAY-0042 | B45: 2273020008 | C45: SU ARITMA | D45: 7300003004 | E45: SU SARFİYATI | F45: 5945.64 | G45: TRY | H45: 20242 | I45: 2025-02-28 00:00:00 | J45: 2025-02-28 00:00:00 | K45: IYS2025000000562 | L45: SDURSUN | M45: KOCAELİ GEBZE DİLOVASI (OTOMATİK)
A46: KAY-0043 | B46: 2273020006 | C46: JENERATOR HIZMETLERI | D46: 7300003004 | E46: SU SARFİYATI | F46: 1033.36 | G46: TRY | H46: 9082 | I46: 2025-01-31 00:00:00 | J46: 2025-01-31 00:00:00 | K46: IYS2025000000014 | L46: SDURSUN | M46: KOCAELİ GEBZE DİLOVASI (OTOMATİK)
A47: KAY-0044 | B47: 2273020007 | C47: KAZAN DAIRESI | D47: 7300003004 | E47: SU SARFİYATI | F47: 10645.58 | G47: TRY | H47: 9082 | I47: 2025-01-31 00:00:00 | J47: 2025-01-31 00:00:00 | K47: IYS2025000000014 | L47: SDURSUN | M47: KOCAELİ GEBZE DİLOVASI (OTOMATİK)
A48: KAY-0045 | B48: 2273020007 | C48: KAZAN DAIRESI | D48: 7300003004 | E48: SU SARFİYATI | F48: 10287.62 | G48: TRY | H48: 23528 | I48: 2025-02-28 00:00:00 | J48: 2025-03-06 00:00:00 | K48: VERBR: Borç/alacak - tüketim | L48: SDURSUN
A49: KAY-0046 | B49: 2273020004 | C49: ALT YAPI HIZMETLERI | D49: 7300003004 | E49: SU SARFİYATI | F49: 27983.27 | G49: TRY | H49: 9082 | I49: 2025-01-31 00:00:00 | J49: 2025-01-31 00:00:00 | K49: IYS2025000000014 | L49: SDURSUN | M49: KOCAELİ GEBZE DİLOVASI (OTOMATİK)
A50: KAY-0047 | B50: 2273020007 | C50: KAZAN DAIRESI | D50: 7300003004 | E50: SU SARFİYATI | F50: 177240.36 | G50: TRY | H50: 20162 | I50: 2025-02-28 00:00:00 | J50: 2025-02-28 00:00:00 | K50: 930-Y32 | L50: EKARADEMIR
A51: KAY-0048 | B51: 2273020005 | C51: KOMPRESOR HIZMETLERI | D51: 7300003004 | E51: SU SARFİYATI | F51: 1033.36 | G51: TRY | H51: 9082 | I51: 2025-01-31 00:00:00 | J51: 2025-01-31 00:00:00 | K51: IYS2025000000014 | L51: SDURSUN | M51: KOCAELİ GEBZE DİLOVASI (OTOMATİK)
A52: KAY-0049 | B52: 2273020005 | C52: KOMPRESOR HIZMETLERI | D52: 7300003004 | E52: SU SARFİYATI | F52: 1189.43 | G52: TRY | H52: 20242 | I52: 2025-02-28 00:00:00 | J52: 2025-02-28 00:00:00 | K52: IYS2025000000562 | L52: SDURSUN | M52: KOCAELİ GEBZE DİLOVASI (OTOMATİK)
A53: KAY-0050 | B53: 2273020007 | C53: KAZAN DAIRESI | D53: 7300003004 | E53: SU SARFİYATI | F53: 18915.76 | G53: TRY | H53: 20242 | I53: 2025-02-28 00:00:00 | J53: 2025-02-28 00:00:00 | K53: IYS2025000000562 | L53: SDURSUN | M53: KOCAELİ GEBZE DİLOVASI (OTOMATİK)
A54: KAY-0051 | B54: 2273020008 | C54: SU ARITMA | D54: 7300003004 | E54: SU SARFİYATI | F54: 5166.81 | G54: TRY | H54: 9082 | I54: 2025-01-31 00:00:00 | J54: 2025-01-31 00:00:00 | K54: IYS2025000000014 | L54: SDURSUN | M54: KOCAELİ GEBZE DİLOVASI (OTOMATİK)
A55: KAY-0052 | B55: 2273020007 | C55: KAZAN DAIRESI | D55: 7300003004 | E55: SU SARFİYATI | F55: 29940.7 | G55: TRY | H55: 13831 | I55: 2025-01-31 00:00:00 | J55: 2025-02-07 00:00:00 | K55: VERBR: Borç/alacak - tüketim | L55: SDURSUN
A56: KAY-0053 | B56: 2273020003 | C56: TEKNIK ORTAK HIZMETL | D56: 7300003004 | E56: SU SARFİYATI | F56: 13181.74 | G56: TRY | H56: 9082 | I56: 2025-01-31 00:00:00 | J56: 2025-01-31 00:00:00 | K56: IYS2025000000014 | L56: SDURSUN | M56: KOCAELİ GEBZE DİLOVASI (OTOMATİK)
A57: KAY-0054 | B57: 2273020007 | C57: KAZAN DAIRESI | D57: 7300003004 | E57: SU SARFİYATI | F57: -10287.62 | G57: TRY | H57: 1000000253 | I57: 2025-02-28 00:00:00 | J57: 2025-02-28 00:00:00 | K57: su sarfı | L57: SDURSUN
A58: KAY-0055 | B58: 2273020007 | C58: KAZAN DAIRESI | D58: 7300003004 | E58: SU SARFİYATI | F58: 10287.62 | G58: TRY | H58: 23431 | I58: 2025-02-28 00:00:00 | J58: 2025-02-28 00:00:00 | K58: su sarfı | L58: SDURSUN
A59: KAY-0056 | B59: 2273020004 | C59: ALT YAPI HIZMETLERI | D59: 7300003004 | E59: SU SARFİYATI | F59: 32198 | G59: TRY | H59: 20242 | I59: 2025-02-28 00:00:00 | J59: 2025-02-28 00:00:00 | K59: IYS2025000000562 | L59: SDURSUN | M59: KOCAELİ GEBZE DİLOVASI (OTOMATİK)
A60: KAY-0057 | B60: 2273020006 | C60: JENERATOR HIZMETLERI | D60: 7300003004 | E60: SU SARFİYATI | F60: 1189.43 | G60: TRY | H60: 20242 | I60: 2025-02-28 00:00:00 | J60: 2025-02-28 00:00:00 | K60: IYS2025000000562 | L60: SDURSUN | M60: KOCAELİ GEBZE DİLOVASI (OTOMATİK)
A61: KAY-0058 | B61: 2273020007 | C61: KAZAN DAIRESI | D61: 7300003004 | E61: SU SARFİYATI | F61: 29940.7 | G61: TRY | H61: 13778 | I61: 2025-01-31 00:00:00 | J61: 2025-01-31 00:00:00 | K61: su sarfı | L61: SDURSUN
A62: KAY-0059 | B62: 2272000003 | C62: SU URETIM | D62: 7300003004 | E62: SU SARFİYATI | F62: 5945.64 | G62: TRY | H62: 20242 | I62: 2025-02-28 00:00:00 | J62: 2025-02-28 00:00:00 | K62: IYS2025000000562 | L62: SDURSUN | M62: KOCAELİ GEBZE DİLOVASI (OTOMATİK)
...

Sheet Satin_Alma
A1: SATIN ALMA VE TEDARİK TAKİBİ
A2: SAT_ID | B2: Talep_No | C2: Talep_Tarihi | D2: Malzeme_Hizmet | E2: Miktar | F2: Birim | G2: Teklif_Durum | H2: Siparis_No | I2: Tedarikçi | J2: Plan_Teslim_Tarihi | K2: Ger_Teslim_Tarihi | L2: Siparis_Tutari_TL | M2: Kabul_Durumu | N2: Gecikme_Nedeni | O2: PRJ_ID | P2: Notlar
A3: SAT-001 | D3: LS-02 SIL sertifikalı seviye transmitteri (T-303 için) | E3: 2 | F3: Adet | G3: Teklif Bekleniyor | J3: 30.11.2026 | M3: Bekliyor | O3: PRJ-2026-002 | P3: HAZOP A-002 aksiyonu kapsamında
A4: SAT-002 | D4: Muayene hizmeti — Out-of-service raporu (Formaldehit tankları) | E4: 1 | F4: Lot | G4: Teklif Hazırlanıyor | I4: Akredite Muayene Firması | J4: 31.12.2026 | M4: Bekliyor | P4: Uygun Değil 7 tank için out-of-service muayenesi
A5: SAT-003 | D5: İskele hizmeti (Pilot Reaktör taşınması) | E5: 1 | F5: Lot | G5: Maliyet Analizinde | J5: 01.12.2026 | L5: 61695.0 | M5: Bekliyor | O5: PRJ-2026-001 | P5: POL-MBO-PRT-2026-001 Rev.01 kalem 3.8

Sheet Risk_Uygunsuzluk
A1: TEKNİK UYGUNSUZLUKLAR, RİSKLER VE HAZOP AKSİYONLARI
A2: Kaynak: HAZOP Aksiyon Listesi (23.09.2026) — 220 aksiyon + tank muayene uygunsuzlukları
A3: UYG_ID | B3: Kaynak | C3: Firma | D3: Tesis | E3: Ünite | F3: Ekipman_Tag | G3: Node_No | H3: HAZOP_No | I3: Aksiyon_Türü | J3: Olası_Neden | K3: Olası_Sonuç | L3: Aksiyon_Açıklaması | M3: Risk_Seviyesi | N3: Sorumlu | O3: Termin | P3: Durum | Q3: Kapama_Tarihi | R3: Notlar
A4: TANK-003 | B4: Tank Muayene | C4: POLİSAN | D4: Gümüş Tesisi | F4: 201.0 | I4: Muayene Uygunsuzluğu | J4: Durum: Uygun Değil | K4: Periyodik muayene yetersizliği; teknik uygunsuzluk riski | L4: Sadece inservice raporu bulunmaktadır. Out of sevice raporu da olmalıdır. Bu sebeple uygunsuzdur. | M4: YÜKSEK | N4: Orhan KARABA | O4: 31.12.2026 | P4: Açık | R4: Tank: FORMALDEHİT TANKI | Hacim: 270.0 m³
A5: TANK-004 | B5: Tank Muayene | C5: POLİSAN | D5: Gümüş Tesisi | F5: 301.0 | I5: Muayene Uygunsuzluğu | J5: Durum: Uygun Değil | K5: Periyodik muayene yetersizliği; teknik uygunsuzluk riski | L5: Sadece inservice raporu bulunmaktadır. Out of sevice raporu da olmalıdır. Bu sebeple uygunsuzdur. | M5: YÜKSEK | N5: Orhan KARABA | O5: 31.12.2026 | P5: Açık | R5: Tank: FORMALDEHIT TANKI-2 | Hacim: 289.0 m³
A6: TANK-005 | B6: Tank Muayene | C6: POLİSAN | D6: Gümüş Tesisi | F6: 302.0 | I6: Muayene Uygunsuzluğu | J6: Durum: Uygun Değil | K6: Periyodik muayene yetersizliği; teknik uygunsuzluk riski | L6: Sadece inservice raporu bulunmaktadır. Out of sevice raporu da olmalıdır. Bu sebeple uygunsuzdur. | M6: YÜKSEK | N6: Orhan KARABA | O6: 31.12.2026 | P6: Açık | R6: Tank: FORMALDEHIT TANKI-3 | Hacim: 289.0 m³
A7: TANK-006 | B7: Tank Muayene | C7: POLİSAN | D7: Gümüş Tesisi | F7: 501.0 | I7: Muayene Uygunsuzluğu | J7: Durum: Uygun Değil | K7: Periyodik muayene yetersizliği; teknik uygunsuzluk riski | L7: Sadece inservice raporu bulunmaktadır. Out of sevice raporu da olmalıdır. Bu sebeple uygunsuzdur. | M7: YÜKSEK | N7: Orhan KARABA | O7: 31.12.2026 | P7: Açık | R7: Tank: FORMALDEHIT TANKI-4 | Hacim: 510.0 m³
A8: TANK-007 | B8: Tank Muayene | C8: POLİSAN | D8: Gümüş Tesisi | F8: 502.0 | I8: Muayene Uygunsuzluğu | J8: Durum: Uygun Değil | K8: Periyodik muayene yetersizliği; teknik uygunsuzluk riski | L8: Sadece inservice raporu bulunmaktadır. Out of sevice raporu da olmalıdır. Bu sebeple uygunsuzdur. | M8: YÜKSEK | N8: Orhan KARABA | O8: 31.12.2026 | P8: Açık | R8: Tank: FORMALDEHIT TANKI-5 | Hacim: 511.0 m³
A9: TANK-008 | B9: Tank Muayene | C9: POLİSAN | D9: Gümüş Tesisi | F9: 101.0 | I9: Muayene Uygunsuzluğu | J9: Durum: Uygun Değil | K9: Periyodik muayene yetersizliği; teknik uygunsuzluk riski | L9: Sadece inservice raporu bulunmaktadır. Out of sevice raporu da olmalıdır. Bu sebeple uygunsuzdur. | M9: YÜKSEK | N9: Orhan KARABA | O9: 31.12.2026 | P9: Açık | R9: Tank: FORMALDEHIT TANKI-6 | Hacim: 115.0 m³
A10: TANK-009 | B10: Tank Muayene | C10: POLİSAN | D10: Gümüş Tesisi | F10: 300.0 | I10: Muayene Uygunsuzluğu | J10: Durum: Uygun Değil | K10: Periyodik muayene yetersizliği; teknik uygunsuzluk riski | L10: Sadece inservice raporu bulunmaktadır. Out of sevice raporu da olmalıdır. Bu sebeple uygunsuzdur. | M10: YÜKSEK | N10: Orhan KARABA | O10: 31.12.2026 | P10: Açık | R10: Tank: FORMALDEHIT TANKI-8 | Hacim: 100.0 m³
A11: TANK-011 | B11: Tank Muayene | C11: POLİSAN | D11: Gümüş Tesisi | F11: 702.0 | I11: Muayene Uygunsuzluğu | J11: Durum: Uygunsuz | K11: Periyodik muayene yetersizliği; teknik uygunsuzluk riski | L11: Sadece inservice raporu bulunmaktadır. Out of sevice raporu da olmalıdır. Bu sebeple uygunsuzdur. | M11: ORTA | N11: Orhan KARABA | O11: 31.12.2026 | P11: Açık | R11: Tank: FENOL TANKI | Hacim: 119.0 m³
A12: TANK-014 | B12: Tank Muayene | C12: POLİSAN | D12: Gümüş Tesisi | F12: 704.0 | I12: Muayene Uygunsuzluğu | J12: Durum: Uygun Değil | K12: Periyodik muayene yetersizliği; teknik uygunsuzluk riski | L12: TANK KOROZYON KAYNAKLI INSPECTION YAPILAMAMIŞTIR. KUMLAMA BOYA GEREKLİDİR. | M12: YÜKSEK | N12: Orhan KARABA | O12: 31.12.2026 | P12: Açık | R12: Tank: KONDENS TANKI | Hacim: 13.0 m³
A13: TANK-016 | B13: Tank Muayene | C13: POLİSAN | D13: Gümüş Tesisi | F13: 102.0 | I13: Muayene Uygunsuzluğu | J13: Durum: Kontrolü yok | K13: Periyodik muayene yetersizliği; teknik uygunsuzluk riski | M13: ORTA | N13: Orhan KARABA | O13: 31.12.2026 | P13: Açık | R13: Tank: SU TANKI | Hacim: 115.0 m³
